Workbook

Sheet Sheet1
A1: Client Code | B1: Client_Name | C1: WireCode | D1: Onboarded on | E1: Aum | F1: RM_Name | G1: Client_Pan | H1: RM_Pan
A2: AQMPC8487H | B2: Aakash Chaudhari | C2: F338Y10 | D2: 45790 | E2: =VLOOKUP(B2,Sheet4!B:G,6,false) -> 151548 | F2: Devashish Upadhyaya | G2: AQMPC8487H | H2: AAQPU3306B
A3: AUEPP9700C | B3: Aarati Samrat Mangure | C3: F447P02 | D3: 45819 | E3: =VLOOKUP(B3,Sheet4!B:G,6,false) -> 1928878 | F3: Anil Gavali | G3: AUEPP9700C | H3: AGHPG7058H
A4: CYXPA8793D | B4: Aarti | C4: F447P02 | D4: 45877 | F4: Anil Gavali | G4: CYXPA8793D | H4: AGHPG7058H
A5: ALCPD9735A | B5: Aarya P Deshpande | C5: F447P03 | D5: 45855 | E5: =VLOOKUP(B5,Sheet4!B:G,6,false) -> 491800 | F5: Kedar Kulkarni | G5: ALCPD9735A | H5: BCJPK7734B
A6: AMAPP0228K | B6: Aayush V Pednekar | C6: F447P03 | D6: 45739 | E6: =VLOOKUP(B6,Sheet4!B:G,6,false) -> 68492 | F6: Kedar Kulkarni | G6: AMAPP0228K | H6: BCJPK7734B
A7: AKXPA9024F | B7: Abhay Ashok Aouti | C7: F338Y08 | D7: 46046 | F7: Abhay Aouti | G7: AKXPA9024F | H7: AKXPA9024F
A8: BYTPD9257N | B8: ABHAY DESHPANDE | C8: F447P03 | D8: 45681 | E8: =VLOOKUP(B8,Sheet4!B:G,6,false) -> 424263 | F8: Kedar Kulkarni | G8: BYTPD9257N | H8: BCJPK7734B
A9: AAVHA3341P | B9: Abhijeet Sangale Huf | C9: F338Y07 | D9: 45983 | E9: =VLOOKUP(B9,Sheet4!B:G,6,false) -> 49883 | F9: Amit Nawle | G9: AAVHA3341P | H9: AFUPN0088A
A10: BMYPB4053R | B10: Abhinav Bhargava | C10: F338Y01 | D10: 45978 | F10: Nitin Mude | G10: BMYPB4053R | H10: AIHPM7502Q
A11: AOWPB9852R | B11: Adhiraj Kedar Dighe | C11: F447P03 | D11: 45935 | E11: =VLOOKUP(B11,Sheet4!B:G,6,false) -> 14294 | F11: Kedar Kulkarni | G11: AOWPB9852R | H11: BCJPK7734B
A12: AJBPD4317K | B12: Aditi Deshpande | C12: F338Y09 | D12: 45793 | E12: =VLOOKUP(B12,Sheet4!B:G,6,false) -> 3004 | F12: Amol Patekar | G12: AJBPD4317K | H12: ALZPP1769R
A13: CEQPG9922R | B13: ADITYA SUNIL GHORPADE | C13: F447P02 | D13: 45938 | E13: =VLOOKUP(B13,Sheet4!B:G,6,false) -> 22549 | F13: Anil Gavali | G13: CEQPG9922R | H13: AGHPG7058H
A14: AKPPK1695N | B14: AJIT KELUSKAR | C14: F447P03 | D14: 45973 | E14: =VLOOKUP(B14,Sheet4!B:G,6,false) -> 17450 | F14: Kedar Kulkarni | G14: AKPPK1695N | H14: BCJPK7734B
A15: CUFPA1931H | B15: Ajithbalachandran | C15: F338Y01 | D15: 45953 | F15: Nitin Mude | G15: CUFPA1931H | H15: AIHPM7502Q
A16: CSPPG4780C | B16: AKSHAY GIRIGOSAVI | C16: F447P03 | D16: 46128 | E16: =VLOOKUP(B16,Sheet4!B:G,6,false) -> 1999 | F16: Kedar Kulkarni | G16: CSPPG4780C | H16: BCJPK7734B
A17: ASEPP4675N | B17: Akshay Patwardhan | C17: FY74603 | D17: 46063 | E17: =VLOOKUP(B17,Sheet4!B:G,6,false) -> 507 | F17: Harshal Bavaskar | G17: ASEPP4675N | H17: CCFPB8266C
A18: CWNPP5058A | B18: Akshay Polake | C18: F447P03 | D18: 45833 | E18: =VLOOKUP(B18,Sheet4!B:G,6,false) -> 26362 | F18: Kedar Kulkarni | G18: CWNPP5058A | H18: BCJPK7734B
A19: AAHPU8282F | B19: Alankar J Urankar | C19: F338Y09 | D19: 46060 | E19: =VLOOKUP(B19,Sheet4!B:G,6,false) -> 120165 | F19: Amol Patekar | G19: AAHPU8282F | H19: ALZPP1769R
A20: AGCPC2588F | B20: ALPESH CHANDAK | C20: F338Y08 | D20: 46091 | E20: =VLOOKUP(B20,Sheet4!B:G,6,false) -> 100636 | F20: Abhay Aouti | G20: AGCPC2588F | H20: AKXPA9024F
A21: BRVPP8587L | B21: Amey Yeshvant Pol | C21: F447P02 | D21: 46066 | E21: =VLOOKUP(B21,Sheet4!B:G,6,false) -> 14815 | F21: Anil Gavali | G21: BRVPP8587L | H21: AGHPG7058H
A22: AGZPJ7377A | B22: Amit V Jadhav | C22: F338Y03 | D22: 45678 | E22: =VLOOKUP(B22,Sheet4!B:G,6,false) -> 430520 | F22: Suhas Tare | G22: AGZPJ7377A | H22: AEYPT3691L
A23: ADIPN2434L | B23: Amol Ashokrao Nikam | C23: F447P02 | D23: 45828 | E23: =VLOOKUP(B23,Sheet4!B:G,6,false) -> 233282 | F23: Anil Gavali | G23: ADIPN2434L | H23: AGHPG7058H
A24: BDQPP7242D | B24: Amol Bajirao Patil | C24: F447P02 | D24: 46048 | E24: =VLOOKUP(B24,Sheet4!B:G,6,false) -> 37842 | F24: Anil Gavali | G24: BDQPP7242D | H24: AGHPG7058H
A25: AQBPD5625K | B25: Amol M Dambalkar | C25: F447P02 | D25: 45889 | E25: =VLOOKUP(B25,Sheet4!B:G,6,false) -> 120542 | F25: Anil Gavali | G25: AQBPD5625K | H25: AGHPG7058H
A26: ALZPP1769R | B26: Amol Vijay Patekar | C26: F338Y09 | D26: 46096 | E26: =VLOOKUP(B26,Sheet4!B:G,6,false) -> 330917 | F26: Amol Patekar | G26: ALZPP1769R | H26: ALZPP1769R
A27: AARPB3063F | B27: Anand P Borude | C27: F447P02 | D27: 45828 | E27: =VLOOKUP(B27,Sheet4!B:G,6,false) -> 1066836 | F27: Anil Gavali | G27: AARPB3063F | H27: AGHPG7058H
... A36: AEXPU4114N | B36: Anjan Atul Uplekar | C36: F447P03 | D36: 45648 | E36: =VLOOKUP(B36,Sheet4!B:G,6,false) -> 342602 | F36: Kedar Kulkarni | G36: AEXPU4114N | H36: BCJPK7734B
A37: AOFPL4920H | B37: Ankush Lonkar | C37: F338Y01 | D37: 46030 | F37: Nitin Mude | G37: AOFPL4920H | H37: AIHPM7502Q
A38: EILPK4203C | B38: Anmol Kaur | C38: F338Y01 | D38: 45904 | F38: Nitin Mude | G38: EILPK4203C | H38: AIHPM7502Q
A39: DDZPM4732C | B39: Anuj Pritesh Mahadik | C39: F447P03 | D39: 45884 | E39: =VLOOKUP(B39,Sheet4!B:G,6,false) -> 27744 | F39: Kedar Kulkarni | G39: DDZPM4732C | H39: BCJPK7734B
A40: EXXPB6758Q | B40: Anushka Bhalekar | C40: F447P01 | D40: 45803 | F40: Bhushan Kulkarni | G40: EXXPB6758Q | H40: APBPK2229R
A41: DBVPS9586N | B41: Aparna Manoj Shelukar | C41: F338Y10 | D41: 46129 | F41: Devashish Upadhyaya | G41: DBVPS9586N | H41: AAQPU3306B
A42: AVKPD4176F | B42: Archana Devhare | C42: F447P02 | D42: 45688 | E42: =VLOOKUP(B42,Sheet4!B:G,6,false) -> 32558 | F42: Anil Gavali | G42: AVKPD4176F | H42: AGHPG7058H
A43: BLFPP9566D | B43: Archana Patil | C43: F447P02 | D43: 45889 | E43: =VLOOKUP(B43,Sheet4!B:G,6,false) -> 5833 | F43: Anil Gavali | G43: BLFPP9566D | H43: AGHPG7058H
A44: BMGPP1011B | B44: Arjun Prakash Powar | C44: F447P02 | D44: 45836 | E44: =VLOOKUP(B44,Sheet4!B:G,6,false) -> 135396 | F44: Anil Gavali | G44: BMGPP1011B | H44: AGHPG7058H
A45: AEUPG8297H | B45: ARUN R GUNJATE | C45: F447P02 | D45: 45818 | E45: =VLOOKUP(B45,Sheet4!B:G,6,false) -> 33932282 | F45: Anil Gavali | G45: AEUPG8297H | H45: AGHPG7058H
A46: AAOPU8306R | B46: Arun Vamanrao Ugale | C46: F338Y10 | D46: 46030 | E46: =VLOOKUP(B46,Sheet4!B:G,6,false) -> 964590 | F46: Devashish Upadhyaya | G46: AAOPU8306R | H46: AAQPU3306B
A47: BMYPG1146G | B47: Aruna Ghatage | C47: F447P02 | D47: 45748 | F47: Anil Gavali | G47: BMYPG1146G | H47: AGHPG7058H
A48: ANFPP8559H | B48: Aruna Yashwant Pol | C48: F447P02 | D48: 45826 | E48: =VLOOKUP(B48,Sheet4!B:G,6,false) -> 152590 | F48: Anil Gavali | G48: ANFPP8559H | H48: AGHPG7058H
...

Sheet Sheet4
A1: Group Code | B1: Investor | C1: Equity | D1: Debt | E1: Hybrid | F1: Other | G1: Total AUM
A2: 40 | B2: Aakash Chaudhari | C2: 151548 | D2: 0 | E2: 0 | F2: 0 | G2: 151548
A3: M00003 | B3: Aarati Samrat Mangure | C3: 1181912 | D3: 0 | E3: 746966 | F3: 0 | G3: 1928878
A4: D00010 | B4: Aarya P Deshpande | C4: 491800 | D4: 0 | E4: 0 | F4: 0 | G4: 491800
A5: 6 | B5: Aayush V Pednekar | C5: 0 | D5: 0 | E5: 68492 | F5: 0 | G5: 68492
A6: 8 | B6: ABHAY DESHPANDE | C6: 424263 | D6: 0 | E6: 0 | F6: 0 | G6: 424263
A7: S00018 | B7: Abhijeet Sangale Huf | C7: 49883 | D7: 0 | E7: 0 | F7: 0 | G7: 49883
A8: D00014 | B8: Adhiraj Kedar Dighe | C8: 0 | D8: 0 | E8: 14294 | F8: 0 | G8: 14294
A9: 41 | B9: Aditi Deshpande | C9: 3004 | D9: 0 | E9: 0 | F9: 0 | G9: 3004
A10: G00021 | B10: ADITYA SUNIL GHORPADE | C10: 22549 | D10: 0 | E10: 0 | F10: 0 | G10: 22549
A11: 84 | B11: AJIT KELUSKAR | C11: 9888 | D11: 0 | E11: 7562 | F11: 0 | G11: 17450
A12: 113 | B12: AKSHAY GIRIGOSAVI | C12: 1999 | D12: 0 | E12: 0 | F12: 0 | G12: 1999
A13: 99 | B13: Akshay Patwardhan | C13: 0 | D13: 0 | E13: 507 | F13: 0 | G13: 507
A14: 52 | B14: Akshay Polake | C14: 25374 | D14: 0 | E14: 988 | F14: 0 | G14: 26362
A15: U00005 | B15: Alankar J Urankar | C15: 120165 | D15: 0 | E15: 0 | F15: 0 | G15: 120165
A16: C00015 | B16: ALPESH CHANDAK | C16: 0 | D16: 0 | E16: 100636 | F16: 0 | G16: 100636
A17: P00036 | B17: Amey Yeshvant Pol | C17: 7388 | D17: 0 | E17: 7427 | F17: 0 | G17: 14815
A18: J00001 | B18: Amit V Jadhav | C18: 430520 | D18: 0 | E18: 0 | F18: 0 | G18: 430520
A19: N00001 | B19: Amol Ashokrao Nikam | C19: 156979 | D19: 0 | E19: 76303 | F19: 0 | G19: 233282
A20: P00033 | B20: Amol Bajirao Patil | C20: 37842 | D20: 0 | E20: 0 | F20: 0 | G20: 37842
A21: D00012 | B21: Amol M Dambalkar | C21: 76891 | D21: 0 | E21: 43651 | F21: 0 | G21: 120542
A22: P00040 | B22: Amol Vijay Patekar | C22: 0 | D22: 0 | E22: 330917 | F22: 0 | G22: 330917
A23: B00004 | B23: Anand P Borude | C23: 506088 | D23: 0 | E23: 560748 | F23: 0 | G23: 1066836
A24: K00020 | B24: Anant S Kulkarni | C24: 25500 | D24: 0 | E24: 0 | F24: 0 | G24: 25500
A25: M00018 | B25: Anant Shivajirao Mane | C25: 22166 | D25: 0 | E25: 0 | F25: 0 | G25: 22166
A26: A00004 | B26: Anil Ashok Agarwal | C26: 173637 | D26: 0 | E26: 0 | F26: 0 | G26: 173637
... A31: T00003 | B31: Anita A Turambekar | C31: 44081 | D31: 0 | E31: 0 | F31: 0 | G31: 44081
A32: 93 | B32: Anjan Atul Uplekar | C32: 0 | D32: 0 | E32: 342602 | F32: 0 | G32: 342602
A33: 15 | B33: Anuj Pritesh Mahadik | C33: 0 | D33: 0 | E33: 27744 | F33: 0 | G33: 27744
A34: 13 | B34: Archana Devhare | C34: 32558 | D34: 0 | E34: 0 | F34: 0 | G34: 32558
A35: 64 | B35: Archana Patil | C35: 5833 | D35: 0 | E35: 0 | F35: 0 | G35: 5833
A36: P00016 | B36: Arjun Prakash Powar | C36: 58648 | D36: 0 | E36: 76748 | F36: 0 | G36: 135396
A37: G00004 | B37: ARUN R GUNJATE | C37: 3679653 | D37: 1475166 | E37: 28777463 | F37: 0 | G37: 33932282
A38: U00003 | B38: Arun Vamanrao Ugale | C38: 112959 | D38: 851631 | E38: 0 | F38: 0 | G38: 964590
A39: P00009 | B39: Aruna Yashwant Pol | C39: 152590 | D39: 0 | E39: 0 | F39: 0 | G39: 152590
A40: P00042 | B40: Arya Rishikesh Patil | C40: 0 | D40: 0 | E40: 105049 | F40: 0 | G40: 105049
A41: S00044 | B41: Ashish M Sanghavi | C41: 2051 | D41: 0 | E41: 0 | F41: 0 | G41: 2051
A42: P00046 | B42: Ashok Dattatray Patil | C42: 5308 | D42: 0 | E42: 0 | F42: 0 | G42: 5308
A43: K00003 | B43: Ashok M Kothawade | C43: 256264 | D43: 0 | E43: 0 | F43: 0 | G43: 256264
A44: 89 | B44: ASHWINI AMBEKAR | C44: 8391 | D44: 0 | E44: 0 | F44: 0 | G44: 8391
...

Sheet Sheet3
A1: RM_Name | B1: RM_Pan | C1: WireCode
A2: Nitin Mude | B2: AIHPM7502Q | C2: F338Y01
A3: Harshal Ghatage | B3: AKCPG4292H | C3: F338Y02
A4: Suhas Tare | B4: AEYPT3691L | C4: F338Y03
A5: Abhijeet Mane | B5: AOMPM5676E | C5: F447P
A6: Avishek Kumar | B6: BIRPK3752P | C6: F338Y12
A7: Rohit Patokar | B7: BPPPP6132M | C7: F338Y14
A8: Ganesh Shankar | B8: BLDPS3686R | C8: F338Y15
A9: Rakesh Bhamare | B9: BASPB6301E | C9: F338Y13
A10: Harshal Bavaskar | B10: CCFPB8266C | C10: FY74603
A11: Sangram Pawar | B11: ENVPP6382L | C11: FY74602
A12: Devashish Upadhyaya | B12: AAQPU3306B | C12: F338Y10
... A25: Neha Kumari | B25: DVUPK0975G | C25: F338Y17
A26: Ashwini Hudlikar | B26: ACNPH5755N
A27: Suraj Jadhav | B27: BNWPJ3454K | C27: F447P07
A28: Shivkumar Mirajkar | B28: ARCPM8393H | C28: F447P05
A29: Rahul Khot | B29: AOLPK9302A | C29: F447P06
A30: Ashwini Patankar | B30: ANHPP9678D | C30: F447P10
A31: Rohan Joshi | B31: AIGPJ1594G | C31: F447P23
A32: Pandurang Zirange | B32: AAKPZ2522L
A33: Venktesh Patil | B33: ERRPP2175M
A34: Hemant Bhalekar | B34: ADYPB4292Q
A35: Khandu Suryawanshi | B35: HWPPS1577G
A36: Prasanna Daddamani | B36: ALNPD4328E | C36: F447P24
A37: Snehal Harale | B37: AHBPH0981P
A38: Rani Jadhav | B38: AVBPJ0383P
