Workbook

Sheet Sheet1
A1: Client ID/PAN | B1: Client Name | C1: Group Code | D1: Onboarded on | E1: AUM (₹) | F1: RM | G1: RM Pan
A2: MAHEN997 | B2: MAHENDRA SHANKAR RANADE | C2: F338Y09 | D2: 40257 | E2: 3.29 Cr | F2: Amol Patokar | G2: =VLOOKUP(F2,Sheet2!B:C,2,FALSE) -> ALZPP1769R
A3: PBANSAL2 | B3: PUSHPA BANSAL | C3: F338Y04 | D3: 43977 | E3: 2.99 Cr | F3: Samir Supsande | G3: =VLOOKUP(F3,Sheet2!B:C,2,FALSE) -> BTJPS5661N
A4: SUBGOVIN | B4: SUBHASH GOVIND SAYKHEDKAR | C4: F338Y07 | D4: 43291 | E4: 2.09 Cr | F4: Amit Nawale | G4: =VLOOKUP(F4,Sheet2!B:C,2,FALSE) -> AFUPN0088A
A5: SRIRANGS | B5: KAUSTUBH SHRIKRISHNA PATWARDHAN | C5: F338Y12 | D5: 43098 | E5: 2.08 Cr | F5: Avishek Kumar | G5: =VLOOKUP(F5,Sheet2!B:C,2,FALSE) -> BIRPK3752P
A6: ARANDIVE | B6: ASHOK DADURAO RANDIVE | C6: F338Y05 | D6: 39153 | E6: 1.98 Cr | F6: Niyaz Sheikh | G6: =VLOOKUP(F6,Sheet2!B:C,2,FALSE) -> BAKPS6882F
A7: MONGINIS | B7: YUVRAJ NILKANTH NEMADE | C7: F338Y14 | D7: 39779 | E7: 1.88 Cr | F7: Rohit Patokar | G7: =VLOOKUP(F7,Sheet2!B:C,2,FALSE) -> BPPPP6132M
A8: SHRIGP28 | B8: SHRICHANDRA GANESH PATANKAR | C8: F338Y02 | D8: 39633 | E8: 1.79 Cr | F8: Harshal Ghatage | G8: =VLOOKUP(F8,Sheet2!B:C,2,FALSE) -> AKCPG4292H
A9: MANISURM | B9: MANISHA SURESH MANE | C9: F338Y12 | D9: 40175 | E9: 1.63 Cr | F9: Avishek Kumar | G9: =VLOOKUP(F9,Sheet2!B:C,2,FALSE) -> BIRPK3752P
A10: DRAHUL80 | B10: RAHUL ASHOK DINGANE | C10: F338Y15 | D10: 43255 | E10: 1.34 Cr | F10: Ganesh Shankar | G10: =VLOOKUP(F10,Sheet2!B:C,2,FALSE) -> BLDPS3686R
A11: PPMOHITE | B11: PANKAJ PRAKASHRAO MOHITE | C11: F338Y02 | D11: 40886 | E11: 1.19 Cr | F11: Harshal Ghatage | G11: =VLOOKUP(F11,Sheet2!B:C,2,FALSE) -> AKCPG4292H
A12: ESTEEM04 | B12: URMILA ASHOK PATIL | C12: F338Y13 | D12: 39512 | E12: 1.18 Cr | F12: Rakesh Bhamare | G12: =VLOOKUP(F12,Sheet2!B:C,2,FALSE) -> BASPB6301E
A13: PATKAR61 | B13: ASHWINI SHRICHANDRA PATANKAR | C13: F338Y02 | D13: 38716 | E13: 1.12 Cr | F13: Harshal Ghatage | G13: =VLOOKUP(F13,Sheet2!B:C,2,FALSE) -> AKCPG4292H
A14: 84650906 | B14: SANJIB KUMAR AMBASTA | C14: F338Y12 | D14: 44923 | E14: 1.07 Cr | F14: Avishek Kumar | G14: =VLOOKUP(F14,Sheet2!B:C,2,FALSE) -> BIRPK3752P
A15: ATULMK70 | B15: ATUL MANOHAR KELKAR | C15: F338Y15 | D15: 44865 | E15: 1.07 Cr | F15: Ganesh Shankar | G15: =VLOOKUP(F15,Sheet2!B:C,2,FALSE) -> BLDPS3686R
A16: RJETHWAN | B16: RANJITA PRAKASH JETHWANI | C16: F338Y04 | D16: 42219 | E16: 1.06 Cr | F16: Samir Supsande | G16: =VLOOKUP(F16,Sheet2!B:C,2,FALSE) -> BTJPS5661N
A17: ADVAVIJA | B17: VIJAY KUMAR KHANNA | C17: F338Y02 | D17: 41772 | E17: 1.06 Cr | F17: Harshal Ghatage | G17: =VLOOKUP(F17,Sheet2!B:C,2,FALSE) -> AKCPG4292H
A18: MALEEHAM | B18: maleeha yusuf mustafa | C18: F338Y02 | D18: 45465 | E18: 1.05 Cr | F18: Harshal Ghatage | G18: =VLOOKUP(F18,Sheet2!B:C,2,FALSE) -> AKCPG4292H
A19: VDIXIT73 | B19: VIJAYKUMAR PRABHAKAR DIXIT | C19: F338Y15 | D19: 43448 | E19: 95.38 L | F19: Ganesh Shankar | G19: =VLOOKUP(F19,Sheet2!B:C,2,FALSE) -> BLDPS3686R
A20: ASHUTOSH | B20: ASHUTOSH KUMAR | C20: F338Y13 | D20: 38199 | E20: 94.45 L | F20: Rakesh Bhamare | G20: =VLOOKUP(F20,Sheet2!B:C,2,FALSE) -> BASPB6301E
A21: TPN00015 | B21: SUNIL VITTHALRAO KOLHE | C21: F338Y14 | D21: 44553 | E21: 86.43 L | F21: Rohit Patokar | G21: =VLOOKUP(F21,Sheet2!B:C,2,FALSE) -> BPPPP6132M
A22: RAHULRSK | B22: RAHUL KASKHEDIKER | C22: F338Y14 | D22: 40468 | E22: 85.92 L | F22: Rohit Patokar | G22: =VLOOKUP(F22,Sheet2!B:C,2,FALSE) -> BPPPP6132M
A23: CRAKESH7 | B23: RAKESH R CHOUDHARY | C23: F338Y05 | D23: 40458 | E23: 74.83 L | F23: Niyaz Sheikh | G23: =VLOOKUP(F23,Sheet2!B:C,2,FALSE) -> BAKPS6882F
A24: SJKAKANI | B24: SACHIN JAYPRAKASH KAKANI | C24: F338Y09 | D24: 43978 | E24: 73.52 L | F24: Amol Patokar | G24: =VLOOKUP(F24,Sheet2!B:C,2,FALSE) -> ALZPP1769R
A25: ALOKRAAM | B25: KHANDELWAL ALOK SHRIRAM | C25: F338Y12 | D25: 40481 | E25: 71.99 L | F25: Avishek Kumar | G25: =VLOOKUP(F25,Sheet2!B:C,2,FALSE) -> BIRPK3752P
A26: KAMLAGP4 | B26: KAMLAKAR GOVIND PATIL | C26: F338Y07 | D26: 39387 | E26: 70.33 L | F26: Amit Nawale | G26: =VLOOKUP(F26,Sheet2!B:C,2,FALSE) -> AFUPN0088A
... A91: DHUMAL77 | B91: DHUMAL MACHINDRA KISAN | C91: F338Y14 | D91: 40560 | E91: 13.65 L | F91: Rohit Patokar | G91: =VLOOKUP(F91,Sheet2!B:C,2,FALSE) -> BPPPP6132M
A92: 99234013 | B92: SANGEETA KUNDAN SHENDE | C92: F338Y04 | D92: 44256 | E92: 12.26 L | F92: Samir Supsande | G92: =VLOOKUP(F92,Sheet2!B:C,2,FALSE) -> BTJPS5661N
A93: SOVITKUN | B93: SOVIT KUMAR NATH | C93: F338Y13 | D93: 40450 | E93: 10.32 L | F93: Rakesh Bhamare | G93: =VLOOKUP(F93,Sheet2!B:C,2,FALSE) -> BASPB6301E
A94: VINAYKAT | B94: VINAY KATYAL | C94: F338Y12 | D94: 41618 | E94: 9.96 L | F94: Avishek Kumar | G94: =VLOOKUP(F94,Sheet2!B:C,2,FALSE) -> BIRPK3752P
A95: 37523279 | B95: MOHAN JAGANNATH GAIKWAD | C95: F338Y02 | D95: 44236 | E95: 8.57 L | F95: Harshal Ghatage | G95: =VLOOKUP(F95,Sheet2!B:C,2,FALSE) -> AKCPG4292H
A96: ARUN0373 | B96: ARUNKUMAR RAJNANDAN SINGH | C96: F338Y13 | D96: 44837 | E96: 7.48 L | F96: Rakesh Bhamare | G96: =VLOOKUP(F96,Sheet2!B:C,2,FALSE) -> BASPB6301E
A97: ANILSK02 | B97: ANIL SADASHIV KARKARE | C97: F338Y02 | D97: 38996 | E97: 4.77 L | F97: Harshal Ghatage | G97: =VLOOKUP(F97,Sheet2!B:C,2,FALSE) -> AKCPG4292H
A98: SHRUPS91 | B98: SHRUTI PRABHAKAR SALE | C98: F338Y02 | D98: 44564 | E98: 4.00 L | F98: Harshal Ghatage | G98: =VLOOKUP(F98,Sheet2!B:C,2,FALSE) -> AKCPG4292H
A99: GOKHALE0 | B99: GOKHALE RAJESH CHIMANLAL | C99: F338Y12 | D99: 44036 | E99: 3.77 L | F99: Avishek Kumar | G99: =VLOOKUP(F99,Sheet2!B:C,2,FALSE) -> BIRPK3752P
A100: 82306446 | B100: SHILA AVINASH PATIL | C100: F338Y12 | D100: 44437 | E100: 3.21 L | F100: Avishek Kumar | G100: =VLOOKUP(F100,Sheet2!B:C,2,FALSE) -> BIRPK3752P
A101: PRASHTAS | B101: PRASHANT MADHUKAR TASGAONKAR | C101: F338Y13 | D101: 44042 | E101: 1.57 L | F101: Rakesh Bhamare | G101: =VLOOKUP(F101,Sheet2!B:C,2,FALSE) -> BASPB6301E
A102: SAVANIN2 | B102: SAVANI OMKAR NAWGHARE | C102: F338Y10 | D102: 45672 | E102: 1.56 L | F102: Devashish Upadhyaya | G102: =VLOOKUP(F102,Sheet2!B:C,2,FALSE) -> AAQPU3306B
A103: THAMAN59 | B103: ASHWANI KUMAR THAMAN | C103: F338Y15 | D103: 44489 | E103: 1.55 L | F103: Ganesh Shankar | G103: =VLOOKUP(F103,Sheet2!B:C,2,FALSE) -> BLDPS3686R
A104: ANANT150 | B104: ANANT SHANKAR KULKARNI | C104: F338Y09 | D104: 39298 | E104: 1.42 L | F104: Amol Patokar | G104: =VLOOKUP(F104,Sheet2!B:C,2,FALSE) -> ALZPP1769R
...

Sheet Sheet2
A1: Wirecode | B1: RM | C1: PAN
A2: F338Y01 | B2: Nitin Mude | C2: AIHPM7502Q
A3: F338Y02 | B3: Harshal Ghatage | C3: AKCPG4292H
A4: F338Y03 | B4: Suhas Tare | C4: AEYPT3691L
A5: F338Y04 | B5: Samir Supsande | C5: BTJPS5661N
A6: F338Y05 | B6: Niyaz Sheikh | C6: BAKPS6882F
A7: F338Y06 | B7: Manali Mude
A8: F338Y07 | B8: Amit Nawale | C8: AFUPN0088A
A9: F338Y08 | B9: Abhay Aouti | C9: AKXPA9024F
A10: F338Y09 | B10: Amol Patokar | C10: ALZPP1769R
A11: F338Y10 | B11: Devashish Upadhyaya | C11: AAQPU3306B
A12: F338Y11 | B12: Ashwini Hudlikar | C12: ACNPH5755N
A13: F338Y12 | B13: Avishek Kumar | C13: BIRPK3752P
A14: F338Y13 | B14: Rakesh Bhamare | C14: BASPB6301E
A15: F338Y14 | B15: Rohit Patokar | C15: BPPPP6132M
A16: F338Y15 | B16: Ganesh Shankar | C16: BLDPS3686R
