Workbook

Sheet Sheet1
A1: Client ID/PAN | B1: Client Name | C1: City | D1: Group Code | E1: RM NAME | F1: RM Pan
A2: AMIT0168 | B2: Amit Mathur | C2: Nashik | D2: FY746 | E2: Suhas Tare | F2: =VLOOKUP(E2,Sheet2!A:B,2,FALSE) -> AEYPT3691L
A3: AAVHR0861B | B3: - | C3: Pune | D3: FY746 | E3: Harshal Bavaskar | F3: =VLOOKUP(E3,Sheet2!A:B,2,FALSE) -> CCFPB8266C
A4: ZAMEES49 | B4: Zameer S Harnesswalla | C4: Pune | D4: FY746 | E4: Harshal Bavaskar | F4: =VLOOKUP(E4,Sheet2!A:B,2,FALSE) -> CCFPB8266C
A5: AORPP2290G | B5: - | C5: Pune | D5: FY746 | E5: Harshal Bavaskar | F5: =VLOOKUP(E5,Sheet2!A:B,2,FALSE) -> CCFPB8266C
A6: ANURACHH | B6: Anurag Chander Chhabra | C6: Pune | D6: FY746 | E6: Sangram Pawar | F6: =VLOOKUP(E6,Sheet2!A:B,2,FALSE) -> ENVPP6382L
A7: YASHWARA | B7: Yashwant Ramchandra Kamkar | C7: Pune | D7: FY746 | E7: Harshal Bavaskar | F7: =VLOOKUP(E7,Sheet2!A:B,2,FALSE) -> CCFPB8266C
A8: HRISHSK7 | B8: Hrishikesh S Khambete | C8: Pune | D8: FY746 | E8: Harshal Bavaskar | F8: =VLOOKUP(E8,Sheet2!A:B,2,FALSE) -> CCFPB8266C
A9: PRAHPAWA | B9: Prashant Narayanrao Pawar | C9: Nashik | D9: FY746 | E9: Suhas Tare | F9: =VLOOKUP(E9,Sheet2!A:B,2,FALSE) -> AEYPT3691L
A10: MADH2308 | B10: Madhur Anil Golegaonkar | C10: Kolhapur | D10: FY746 | E10: Dhananjay Yadav | F10: =VLOOKUP(E10,Sheet2!A:B,2,FALSE) -> ABXPY6459K
A11: 42146427 | B11: Prashant Laxmanrao Shinde | C11: Pune | D11: FY746 | E11: Harshal Bavaskar | F11: =VLOOKUP(E11,Sheet2!A:B,2,FALSE) -> CCFPB8266C
A12: MAYUR485 | B12: Mayur Tanajirao Suryawanshi | C12: Nashik | D12: FY746 | E12: Suhas Tare | F12: =VLOOKUP(E12,Sheet2!A:B,2,FALSE) -> AEYPT3691L
A13: TUSHGORA | B13: Tushar Madhukar Gorade | C13: Nashik | D13: FY746 | E13: Suhas Tare | F13: =VLOOKUP(E13,Sheet2!A:B,2,FALSE) -> AEYPT3691L
A14: SSURDE95 | B14: Sukumar Pralhad Surde | C14: Pune | D14: FY746 | E14: Sangram Pawar | F14: =VLOOKUP(E14,Sheet2!A:B,2,FALSE) -> ENVPP6382L
A15: PRSHENOY | B15: Pundalik Raghuvir Shenoy | C15: Pune | D15: FY746 | E15: Harshal Bavaskar | F15: =VLOOKUP(E15,Sheet2!A:B,2,FALSE) -> CCFPB8266C
A16: RAJE0270 | B16: Rajesh Kumar Gupta | C16: Pune | D16: FY746 | E16: Avishek Kumar | F16: =VLOOKUP(E16,Sheet2!A:B,2,FALSE) -> BIRPK3752P
A17: 1988LOKE | B17: Lokesh Namdeo Bhangale | C17: Pune | D17: FY746 | E17: Harshal Bavaskar | F17: =VLOOKUP(E17,Sheet2!A:B,2,FALSE) -> CCFPB8266C
A18: VILA1966 | B18: Vilas Bhagoji Joshi | C18: Kolhapur | D18: FY746 | E18: Bhushan Kulkarni | F18: =VLOOKUP(E18,Sheet2!A:B,2,FALSE) -> APBPK2229R
A19: SANDHDE9 | B19: Sandhya Deep Chhabra | C19: Pune | D19: FY746 | E19: Sangram Pawar | F19: =VLOOKUP(E19,Sheet2!A:B,2,FALSE) -> ENVPP6382L
A20: SUNI1070 | B20: Shinde Sunita Subodh | C20: Pune | D20: FY746 | E20: Avishek Kumar | F20: =VLOOKUP(E20,Sheet2!A:B,2,FALSE) -> BIRPK3752P
A21: RAVID985 | B21: Ravi Dattu Shinde | C21: Pune | D21: FY746 | E21: Harshal Bavaskar | F21: =VLOOKUP(E21,Sheet2!A:B,2,FALSE) -> CCFPB8266C
A22: MKARLE11 | B22: Mahesh Avadhut Karle | C22: Pune | D22: FY746 | E22: Sangram Pawar | F22: =VLOOKUP(E22,Sheet2!A:B,2,FALSE) -> ENVPP6382L
A23: PHUKES81 | B23: Sandeep Phuke | C23: Pune | D23: FY746 | E23: Harshal Bavaskar | F23: =VLOOKUP(E23,Sheet2!A:B,2,FALSE) -> CCFPB8266C
A24: SHASHIM3 | B24: Shashikant Mangaldas Chandan | C24: Pune | D24: FY746 | E24: Avishek Kumar | F24: =VLOOKUP(E24,Sheet2!A:B,2,FALSE) -> BIRPK3752P
A25: 19142026 | B25: Manjusha Sachin Chavan | C25: Kolhapur | D25: FY746 | E25: Devashish Upadhyaya | F25: =VLOOKUP(E25,Sheet2!A:B,2,FALSE) -> AAQPU3306B
A26: 11842067 | B26: Samir Suryakant Pandit | C26: Nashik | D26: FY746 | E26: Suhas Tare | F26: =VLOOKUP(E26,Sheet2!A:B,2,FALSE) -> AEYPT3691L
A27: 13174000 | B27: Priyanka Kirankumar Salve | C27: Pune | D27: FY746 | E27: Harshal Bavaskar | F27: =VLOOKUP(E27,Sheet2!A:B,2,FALSE) -> CCFPB8266C
A28: DINVJO | B28: Dinesh V Joshi | C28: Pune | D28: FY746 | E28: Sangram Pawar | F28: =VLOOKUP(E28,Sheet2!A:B,2,FALSE) -> ENVPP6382L
A29: SFURTI90 | B29: Sfurti Dharmrakshit Sahare | C29: Pune | D29: FY746 | E29: Harshal Bavaskar | F29: =VLOOKUP(E29,Sheet2!A:B,2,FALSE) -> CCFPB8266C
A30: 1988SITA | B30: Sitaram Dilip Bhosale | C30: Kolhapur | D30: FY746 | E30: Kedar Kulkarni | F30: =VLOOKUP(E30,Sheet2!A:B,2,FALSE) -> BCJPK7734B
A31: DHANAP77 | B31: Dhananjay Pandurang Patil | C31: Pune | D31: FY746 | E31: Harshal Bavaskar | F31: =VLOOKUP(E31,Sheet2!A:B,2,FALSE) -> CCFPB8266C
A32: 81077987 | B32: Rajan Jayagobinda Palai | C32: Pune | D32: FY746 | E32: Sangram Pawar | F32: =VLOOKUP(E32,Sheet2!A:B,2,FALSE) -> ENVPP6382L
A33: KHOLE285 | B33: Shruti Sanjay Khole | C33: Pune | D33: FY746 | E33: Sangram Pawar | F33: =VLOOKUP(E33,Sheet2!A:B,2,FALSE) -> ENVPP6382L
A34: GARIMAK2 | B34: Garima Kumari | C34: Pune | D34: FY746 | E34: Avishek Kumar | F34: =VLOOKUP(E34,Sheet2!A:B,2,FALSE) -> BIRPK3752P
A35: DKPATKAR | B35: Dhanshri Kailash Patkar | C35: Nashik | D35: FY746 | E35: Devashish Upadhyaya | F35: =VLOOKUP(E35,Sheet2!A:B,2,FALSE) -> AAQPU3306B
A36: PRACHIP3 | B36: Prachi Pauranik | C36: Pune | D36: FY746 | E36: Harshal Bavaskar | F36: =VLOOKUP(E36,Sheet2!A:B,2,FALSE) -> CCFPB8266C
A37: 98307865 | B37: Umesh Sheshrao Chape | C37: Pune | D37: FY746 | E37: Harshal Bavaskar | F37: =VLOOKUP(E37,Sheet2!A:B,2,FALSE) -> CCFPB8266C
A38: 46418352 | B38: Manisha Sandip Mhaisekar | C38: Pune | D38: FY746 | E38: Harshal Bavaskar | F38: =VLOOKUP(E38,Sheet2!A:B,2,FALSE) -> CCFPB8266C
A39: 56306630 | B39: Akangi Sharma | C39: Pune | D39: FY746 | E39: Sangram Pawar | F39: =VLOOKUP(E39,Sheet2!A:B,2,FALSE) -> ENVPP6382L
A40: RANU1972 | B40: Renu Devi | C40: Pune | D40: FY746 | E40: Harshal Bavaskar | F40: =VLOOKUP(E40,Sheet2!A:B,2,FALSE) -> CCFPB8266C
...

Sheet Sheet2
A1: RM | B1: PAN
A2: Nitin Mude | B2: AIHPM7502Q
A3: Harshal Ghatage | B3: AKCPG4292H
A4: Suhas Tare | B4: AEYPT3691L
A5: Abhijeet Mane | B5: AOMPM5676E
A6: Avishek Kumar | B6: BIRPK3752P
A7: Rohit Patokar | B7: BPPPP6132M
A8: Ganesh Shankar | B8: BLDPS3686R
A9: Rakesh Bhamare | B9: BASPB6301E
A10: Harshal Bavaskar | B10: CCFPB8266C
A11: Sangram Pawar | B11: ENVPP6382L
A12: Devashish Upadhyaya | B12: AAQPU3306B
... A28: Shivkumar Mirajkar | B28: ARCPM8393H

Sheet Sheet3
A1: Leader | B1: Leader PAN | C1: Manager | D1: Manager PAN | E1: RM | F1: RM PAN | G1: MA | H1: MA PAN | I1: id | J1: Emp | K1: Emp Manager | L1: manger id | M1: pan | N1: RM PAN
A2: Nitin Mude | B2: ABC | C2: Suhas Tare | D2: xyz | E2: Abhay | F2: ytf | G2: joshi | H2: kyb | I2: 1 | J2: Nitin Mude | L2: null | M2: abc
A3: Nitin Mude | B3: ABC | C3: Suhas Tare | D3: xyz | E3: Amit | I3: 2 | J3: Suhas Tare | K3: Nitin Mude | L3: 1 | M3: as
A4: Nitin Mude | B4: ABC | C4: Suhas Tare | D4: xyz | E4: amol | I4: 3 | J4: Abhay | K4: Suhas Tare | L4: 2 | M4: asd
A5: Nitin Mude | B5: ABC | C5: Suhas Tare | D5: xyz | I5: 4 | J5: Amit | K5: Suhas Tare | L5: 2 | M5: ee
A6: Nitin Mude | B6: ABC | C6: Suhas Tare | D6: xyz | I6: 5 | J6: joshi | K6: Abhay | L6: 3 | M6: qwe
A7: Nitin Mude | B7: ABC | C7: Suhas Tare | D7: xyz
A8: Nitin Mude | B8: ABC | C8: Suhas Tare | D8: xyz
A9: Nitin Mude | B9: ABC
A10: Nitin Mude | B10: ABC
A11: Nitin Mude | B11: ABC
A12: Nitin Mude | B12: ABC
A13: Nitin Mude | B13: ABC
A14: Nitin Mude | B14: ABC
A15: Nitin Mude | B15: ABC
A16: Nitin Mude | B16: ABC
A17: Nitin Mude | B17: ABC
A18: Nitin Mude | B18: ABC
A19: Nitin Mude | B19: ABC
A20: Nitin Mude | B20: ABC

Sheet Sheet5
A1: ID | B1: NAME | C1: PAN | D1: MANAGER ID | E1: wire code | F1: employee id
A2: 1 | B2: Nitin Mude | C2: AIHPM7502Q | D2: null | E2: F338Y01 | F2: C001
A3: 2 | B3: Harshal Ghatage | C3: AKCPG4292H | D3: 1 | E3: F338Y02 | F3: C002
A4: 3 | B4: Suhas Tare | C4: AEYPT3691L | D4: 1 | E4: F338Y03 | F4: C003
A5: 4 | B5: Abhijeet Mane | C5: AOMPM5676E | D5: 1 | E5: F447P | F5: C004
A6: 5 | B6: Avishek Kumar | C6: BIRPK3752P | D6: 2 | E6: F338Y12 | F6: C021
A7: 6 | B7: Rohit Patokar | C7: BPPPP6132M | D7: 2 | E7: F338Y14 | F7: C025
A8: 7 | B8: Ganesh Shankar | C8: BLDPS3686R | D8: 2 | E8: F338Y15 | F8: C019
A9: 8 | B9: Rakesh Bhamare | C9: BASPB6301E | D9: 2 | E9: F338Y13 | F9: C029
A10: 9 | B10: Harshal Bavaskar | C10: CCFPB8266C | D10: 2 | E10: FY746 | F10: C012
A11: 10 | B11: Sangram Pawar | C11: ENVPP6382L | D11: 2 | E11: FY746 | F11: C011
A12: 11 | B12: Devashish Upadhyaya | C12: AAQPU3306B | D12: 3 | E12: F338Y10 | F12: C024
A13: 12 | B13: Amit Nawale | C13: AFUPN0088A | D13: 3 | E13: F338Y07 | F13: C022
A14: 13 | B14: Amol Patekar | C14: ALZPP1769R | D14: 3 | E14: F338Y09 | F14: C020
... A21: 20 | B21: Dhananjay Yadav | C21: ABXPY6459K | D21: 4 | E21: F447P04 | F21: C027
A22: 21 | B22: Pranab Pradhan | C22: CHOPP7017D | D22: 2 | F22: C028
A23: 22 | B23: Bishwa Chatterjee | C23: BVBPC5708E | D23: 2 | F23: C032
A24: 23 | B24: Sinoo Biswas | C24: CPOPS8080P | D24: 2 | F24: C031
A25: 24 | B25: Neha Kumari | C25: DVUPK0975G | D25: 2 | F25: C030
A26: 25 | B26: Ashwini Hudlikar | C26: ACNPH5755N | D26: 3 | F26: C016
A27: 26 | B27: Suraj Jadhav | C27: BNWPJ3454K | D27: 4 | F27: C034
A28: 27 | B28: Shivkumar Mirajkar | C28: ARCPM8393H | D28: 4 | F28: C033
